Workbook

Sheet Measurment 3rd floor
B1: TS INTERIOR Date:- 18.07.2020
B2: Site Name:-Dr. Dy Patil Nursing Hostel, Pimpri (3 Floor)
B3: Measurement-Sheet
B5: S.No. | D5: No. | E5: Length | F5: Breadth | G5: Quantity
E6: Feet-inch | F6: Feet-inch
A8: 301 | B8: 1 | C8: Tile Floor Fitting (1800x1200) | D8: 1 | E8: 6 | F8: 5 | G8: =E8*F8 -> 30
C9: Living Area | D9: 1 | E9: 19.33 | F9: 12.55 | G9: =E9*F9 -> 242.5915
D10: 1 | E10: 15.75 | F10: 10.8 | G10: =E10*F10 -> 170.1
D11: 1 | E11: 9.5 | F11: 6.33 | G11: =E11*F11 -> 60.135
D12: 1 | E12: 4.41 | F12: 2.91 | G12: =E12*F12 -> 12.8331
C13: Umbra | D13: 1 | E13: 2.41 | F13: 0.33 | G13: =E13*F13 -> 0.7953
C14: Umbra | D14: 2 | E14: 2.83 | F14: 0.75 | G14: =E14*F14 -> 2.1225
F15: Total | G15: =SUM(G8:G14) -> 518.5774
B16: 2 | C16: Tile Wash By Cera Clean & Cement Grout Filling
C17: Same Above Qty. | F17: Total | G17: 518.58
B19: 3 | C19: P V C Sheet Covering
C20: Same Above Qty. | F20: Total | G20: 518.58
B22: 4 | C22: Epoxy Grout Filling
C23: Same Above Qty. | F23: Total | G23: 518.58
B26: 5 | C26: I.P.S. Cement Finish Ghotai (Scceding) | D26: 1 | E26: 6 | F26: 5 | G26: =E26*F26 -> 30
D27: 1 | E27: 19.33 | F27: 12.55 | G27: =E27*F27 -> 242.5915
D28: 1 | E28: 15.75 | F28: 10.8 | G28: =E28*F28 -> 170.1
D29: 1 | E29: 9.5 | F29: 6.33 | G29: =E29*F29 -> 60.135
D30: 1 | E30: 4.41 | F30: 2.91 | G30: =E30*F30 -> 12.8331
D31: 1 | E31: 2.41 | F31: 0.33 | G31: =E31*F31 -> 0.7953
D32: 2 | E32: 2.83 | F32: 0.75 | G32: =E32*F32 -> 2.1225
D33: 1 | E33: 10.25 | F33: 10.08 | G33: =E33*F33 -> 103.32
F34: Total | G34: 518.58
B36: 6 | C36: Marble Top,Border & Jamb Fitting | D36: 1 | E36: 3.08 | G36: 3.08
F37: Total | G37: 3.08
B39: 7 | C39: Dhar Cuttting & Demolish | D39: 1 | E39: 3.08 | G39: 3.08
F40: Total | G40: 3.08
B42: 8 | C42: 3/4" Champer | D42: 2 | E42: 3.08 | G42: 6.16
F43: Total | G43: 6.16
B45: 9 | C45: Tile Skirting & Border Fitting (1800x1200) | D45: 1 | E45: 9.33 | G45: 9.33
D46: 1 | E46: 15 | G46: 15
D47: 1 | E47: 12.25 | G47: 12.25
D48: 1 | E48: 3.83 | G48: 3.83
D49: 1 | E49: 4.33 | G49: 4.33
D50: 1 | E50: 13.66 | G50: 13.66
...

Sheet Abc 
A1: TS INTERIOR Date:-21.07.2020
A2: ABSTRACT SHEET (3rd Floor)
A3: S.No. | B3: Description | C3: Quqntity | D3: S.No. | E3: Description | F3: Quqntity
C4: Sft./Rft. | F4: Sft./Rft.
A5: 1 | B5: Tile Floor(1500x800) | C5: =+'Measurment 3rd floor'!G14 -> 2.1225 | D5: =+A44+1 -> 4 | E5: Tile Border (1500x800) | F5: =+'Measurment 3rd floor'!G94 -> 2
C6: =+'Measurment 3rd floor'!G491 -> 0 | F6: =+'Measurment 3rd floor'!G545 -> 4.16
C7: =+'Measurment 3rd floor'!#REF! -> #REF! | F7: =+'Measurment 3rd floor'!#REF! -> #REF!
C8: =+'Measurment 3rd floor'!#REF! -> #REF! | F8: =+'Measurment 3rd floor'!#REF! -> #REF!
C9: =+'Measurment 3rd floor'!#REF! -> #REF! | F9: =+'Measurment 3rd floor'!#REF! -> #REF!
C10: =+'Measurment 3rd floor'!#REF! -> #REF! | F10: =+'Measurment 3rd floor'!#REF! -> #REF!
C11: =+'Measurment 3rd floor'!#REF! -> #REF! | F11: =+'Measurment 3rd floor'!#REF! -> #REF!
C12: =+'Measurment 3rd floor'!#REF! -> #REF! | F12: =+'Measurment 3rd floor'!#REF! -> #REF!
C13: =+'Measurment 3rd floor'!#REF! -> #REF! | F13: =+'Measurment 3rd floor'!#REF! -> #REF!
C14: =+'Measurment 3rd floor'!#REF! -> #REF! | F14: =+'Measurment 3rd floor'!#REF! -> #REF!
C15: =+'Measurment 3rd floor'!#REF! -> #REF! | E15: Total | F15: =SUM(F5:F14) -> #REF!
C16: =+'Measurment 3rd floor'!#REF! -> #REF!
B17: Total | C17: =SUM(C5:C16) -> #REF! | D17: =+D5+1 -> 5 | E17: Tile Floor (800x400) | F17: =+'Measurment 3rd floor'!G247 -> 0
F18: =+'Measurment 3rd floor'!#REF! -> #REF!
A19: =+A5+1 -> 2 | B19: Tile Skirting (1500x800) | C19: =+'Measurment 3rd floor'!G44 -> 0 | F19: =+'Measurment 3rd floor'!#REF! -> #REF!
C20: =+'Measurment 3rd floor'!G63 -> 2.75 | F20: =+'Measurment 3rd floor'!#REF! -> #REF!
C21: =+'Measurment 3rd floor'!G507 -> 0 | F21: =+'Measurment 3rd floor'!#REF! -> #REF!
C22: =+'Measurment 3rd floor'!G524 -> 0 | F22: =+'Measurment 3rd floor'!#REF! -> #REF!
C23: =+'Measurment 3rd floor'!#REF! -> #REF! | F23: =+'Measurment 3rd floor'!#REF! -> #REF!
C24: =+'Measurment 3rd floor'!#REF! -> #REF! | F24: =+'Measurment 3rd floor'!#REF! -> #REF!
C25: =+'Measurment 3rd floor'!#REF! -> #REF! | F25: =+'Measurment 3rd floor'!#REF! -> #REF!
C26: =+'Measurment 3rd floor'!#REF! -> #REF! | F26: =+'Measurment 3rd floor'!#REF! -> #REF!
C27: =+'Measurment 3rd floor'!#REF! -> #REF! | F27: =+'Measurment 3rd floor'!#REF! -> #REF!
C28: =+'Measurment 3rd floor'!#REF! -> #REF! | E28: Total | F28: =SUM(F17:F27) -> #REF!
C29: =+'Measurment 3rd floor'!#REF! -> #REF!
C30: =+'Measurment 3rd floor'!#REF! -> #REF! | D30: =+D17+1 -> 6 | E30: Tile Dado(750x250) | F30: =+'Measurment 3rd floor'!G425 -> 7.08
C31: =+'Measurment 3rd floor'!#REF! -> #REF! | F31: =+'Measurment 3rd floor'!#REF! -> #REF!
C32: =+'Measurment 3rd floor'!#REF! -> #REF! | F32: =+'Measurment 3rd floor'!#REF! -> #REF!
C33: =+'Measurment 3rd floor'!#REF! -> #REF! | F33: =+'Measurment 3rd floor'!#REF! -> #REF!
C34: =+'Measurment 3rd floor'!#REF! -> #REF! | F34: =+'Measurment 3rd floor'!#REF! -> #REF!
C35: =+'Measurment 3rd floor'!#REF! -> #REF! | F35: =+'Measurment 3rd floor'!#REF! -> #REF!
C36: =+'Measurment 3rd floor'!#REF! -> #REF! | F36: =+'Measurment 3rd floor'!#REF! -> #REF!
C37: =+'Measurment 3rd floor'!#REF! -> #REF! | F37: =+'Measurment 3rd floor'!#REF! -> #REF!
C38: =+'Measurment 3rd floor'!#REF! -> #REF! | F38: =+'Measurment 3rd floor'!#REF! -> #REF!
C39: =+'Measurment 3rd floor'!#REF! -> #REF! | F39: =+'Measurment 3rd floor'!#REF! -> #REF!
C40: =+'Measurment 3rd floor'!#REF! -> #REF! | F40: =+'Measurment 3rd floor'!#REF! -> #REF!
...

Sheet Total
A1: Supplier Details | C1: Recever Details
A2: TS INTERIOR | C2: Site Name :-Dr. Dy Patil Nursing Hostel,Pimpri
A3: Flat No A/1104,Royal Corts Anand Park | C3: Date :-12.10.2020
A4: Dange Chowk Thergaon Pune -411033
A5: PHONE :-9822834278
A6: Bill For 3rd Floor Tile & Italian Marble Floor & Granite Work
A7: S.No. | B7: Description | C7: Unit | D7: Total | E7: Rate | F7: Rate | G7: Amount
D8: Quantity | E8: OLD | G8: Rs.
A9: 1 | B9: Tile Floor(1500x800) | C9: Sft | D9: =+'Abc '!C17 -> #REF! | E9: 50.4 | F9: 50.4 | G9: =+F9*D9 -> #REF!
A11: =+A9+1 -> 2 | B11: Tile Skirting (1500x800) | C11: Rft | D11: =+'Abc '!C42 -> #REF! | E11: 50.4 | F11: 50.4 | G11: =+F11*D11 -> #REF!
A13: =+A11+1 -> 3 | B13: Tile Dado(1500x800) | C13: Sft | D13: =+'Abc '!C55 -> #REF! | E13: 70 | F13: 70 | G13: =+F13*D13 -> #REF!
A15: =+A13+1 -> 4 | B15: Tile Border (1500x800) | C15: Rft | D15: =+'Abc '!F15 -> #REF! | E15: 50.4 | F15: 50.4 | G15: =+F15*D15 -> #REF!
A17: =+A15+1 -> 5 | B17: Tile Floor (800x400) | C17: Sft | D17: =+'Abc '!F28 -> #REF! | E17: 50.4 | F17: 50.4 | G17: =+F17*D17 -> #REF!
A19: =+A17+1 -> 6 | B19: Tile Dado(750x250) | C19: Sft | D19: =+'Abc '!F41 -> #REF! | E19: 50.4 | F19: 50.4 | G19: =+F19*D19 -> #REF!
A21: =+A19+1 -> 7 | B21: Tile Border (25mmx600) | C21: Rft | D21: =+'Abc '!F54 -> #REF! | E21: 33.6 | F21: 33.6 | G21: =+F21*D21 -> #REF!
A23: =+A21+1 -> 8 | B23: Tile Groove Grouting | C23: Sft/Rft | D23: =+'Abc '!C80 -> #REF! | E23: 26.4 | F23: 26.4 | G23: =+F23*D23 -> #REF!
A25: =+A23+1 -> 9 | B25: Tile Acid wash Cleaning | C25: Sft/Rft | D25: =+'Abc '!C120 -> #REF! | E25: 4 | F25: 4 | G25: =+F25*D25 -> #REF!
A27: =+A25+1 -> 10 | B27: Italian Marble Dado | C27: Sft | D27: =+'Abc '!C134 -> #REF! | E27: 110 | F27: 110 | G27: =+F27*D27 -> #REF!
A29: =+A27+1 -> 11 | B29: Italian Marble Dado Mirror Polish | C29: Sft | D29: =+'Abc '!C148 -> #REF! | E29: 60 | F29: 60 | G29: =+F29*D29 -> #REF!
A31: =+A29+1 -> 12 | B31: Italian Marble Border | C31: Rft | D31: =+'Abc '!F158 -> #REF! | E31: 90 | F31: 90 | G31: =+F31*D31 -> #REF!
A33: =+A31+1 -> 13 | B33: Italian Marble Border Mirror Polish | C33: Rft/Sft | D33: =+'Abc '!C213 -> #REF! | E33: 60 | F33: 60 | G33: =+F33*D33 -> #REF!
A35: =+A33+1 -> 14 | B35: Italian Marble Skirting | C35: Rft | D35: =+'Abc '!F188 -> #REF! | E35: 90 | F35: 90 | G35: =+F35*D35 -> #REF!
A37: =+A35+1 -> 15 | B37: Italian Marble Skirting Mirror Polish | C37: Rft | D37: =+'Abc '!F212 -> #REF! | E37: 60 | F37: 60 | G37: =+F37*D37 -> #REF!
A39: =+A37+1 -> 16 | B39: Italian Marble Window/Door Jamb | C39: Rft | D39: =+'Abc '!C280 -> #REF! | E39: 90 | F39: 90 | G39: =+F39*D39 -> #REF!
A41: =+A39+1 -> 17 | B41: Italian Marble Window/Door Jamb Mirror Polish | C41: Rft | D41: =+'Abc '!F278 -> #REF! | E41: 60 | F41: 60 | G41: =+F41*D41 -> #REF!
A43: =+A41+1 -> 18 | B43: Italian Marble Counter | C43: Rft | D43: =+'Abc '!C292 -> #REF! | E43: 720 | F43: 720 | G43: =+F43*D43 -> #REF!
A45: =+A43+1 -> 19 | B45: Italian Marble Basin Counter | C45: Rft | D45: =+'Abc '!C305 -> #REF! | E45: 720 | F45: 720 | G45: =+F45*D45 -> #REF!
A47: =+A45+1 -> 20 | B47: Italian Marble Counter Top Mirror Polish | C47: Sft | D47: =+'Abc '!C318 -> #REF! | E47: 60 | F47: 60 | G47: =+F47*D47 -> #REF!
A49: =+A47+1 -> 21 | B49: Italian Marble Floor | C49: Sft | D49: =+'Abc '!C320 -> #REF! | E49: 90 | F49: 90 | G49: =+F49*D49 -> #REF!
A51: =+A49+1 -> 22 | B51: Italian Marble Desgin Floor | C51: Sft | D51: =+'Abc '!C322 -> #REF! | E51: 1100 | F51: 800 | G51: =+F51*D51 -> #REF!
E53: C/F | F53: C/F | G53: =SUM(G9:G52) -> #REF!
E55: B/F | F55: B/F | G55: =+G53 -> #REF!
A57: =+A51+1 -> 23 | B57: Italian Marble Floor Mirror Polish | C57: Sft | D57: =+'Abc '!C327 -> #REF! | E57: 60 | F57: 60 | G57: =+F57*D57 -> #REF!
A59: =+A57+1 -> 24 | B59: 9'' Design Skirting 4 Border Making & Polish | C59: Rft | D59: =+'Abc '!F281 -> #REF! | E59: 1000 | F59: 800 | G59: =+F59*D59 -> #REF!
A61: =+A59+1 -> 25 | B61: Granite Window Suport Jamb | C61: Rft | D61: =+'Abc '!F314 -> #REF! | E61: 72 | F61: 72 | G61: =+F61*D61 -> #REF!
A63: =+A61+1 -> 26 | B63: Granite Dado | C63: Sft | D63: =+'Abc '!F327 -> #REF! | E63: 72 | F63: 72 | G63: =+F63*D63 -> #REF!
A65: =+A63+1 -> 27 | B65: Granite Floor | C65: Sft | D65: =+'Abc '!F329 -> #REF! | E65: 72 | F65: 72 | G65: =+F65*D65 -> #REF!
A67: =+A65+1 -> 28 | B67: Granite Skirting | C67: Rft | D67: =+'Abc '!F331 -> #REF! | E67: 66 | F67: 66 | G67: =+F67*D67 -> #REF!
A69: =+A67+1 -> 29 | B69: Granite Border | C69: Rft | D69: =+'Abc '!C347 -> #REF! | E69: 72 | F69: 72 | G69: =+F69*D69 -> #REF!
A71: =+A69+1 -> 30 | B71: Granider Raugh Making | C71: Sft | D71: =+'Abc '!C360 -> #REF! | E71: 18 | F71: 18 | G71: =+F71*D71 -> #REF!
...

Sheet Sheet1
A1: Supplier Details | C1: Recever Details
A2: TS INTERIOR | C2: Site Name :-Dr. Dy Patil Nursing Hostel,Pimpri
A3: Flat No A/1104,Royal Corts Anand Park | C3: Date :-12.10.2020
A4: Dange Chowk Thergaon Pune -411033
A5: PHONE :-9822834278
A6: Bill For 3rd Floor Tile & Italian Marble Floor & Granite Work
A7: S.No. | B7: Description | C7: Unit | D7: Bill | E7: Bill | F7: Bill | G7: Ground | H7: Stair | I7: Total | J7: Rate | K7: Total
D8: No.03 | E8: No.01 | F8: No.02 | G8: Floor | H8: Case | I8: Qty
A9: 1 | B9: Tile Floor(1500x800) | C9: Sft | D9: =+'Abc '!C17 -> #REF! | E9: 1615.48 | F9: 2504.28 | H9: 94.84 | I9: =+SUM(D9:H9) -> #REF! | J9: 50.4 | K9: =+J9*I9 -> #REF!
A11: =+A9+1 -> 2 | B11: Tile Skirting (1500x800) | C11: Rft | D11: =+'Abc '!C42 -> #REF! | E11: 398.76 | F11: 708.36 | H11: 29.15 | I11: =+SUM(D11:H11) -> #REF! | J11: 50.4 | K11: =+J11*I11 -> #REF!
A13: =+A11+1 -> 3 | B13: Tile Dado(1500x800) | C13: Sft | D13: =+'Abc '!C55 -> #REF! | E13: 481.01 | F13: 1032.93 | I13: =+SUM(D13:H13) -> #REF! | J13: 70 | K13: =+J13*I13 -> #REF!
A15: =+A13+1 -> 4 | B15: Tile Border (1500x800) | C15: Rft | D15: =+'Abc '!F15 -> #REF! | E15: 7.16 | F15: 165.23 | I15: =+SUM(D15:H15) -> #REF! | J15: 50.4 | K15: =+J15*I15 -> #REF!
A17: =+A15+1 -> 5 | B17: Tile Floor (800x400) | C17: Sft | D17: =+'Abc '!F28 -> #REF! | E17: 87.93 | F17: 174.86 | I17: =+SUM(D17:H17) -> #REF! | J17: 50.4 | K17: =+J17*I17 -> #REF!
A19: =+A17+1 -> 6 | B19: Tile Dado(750x250) | C19: Sft | D19: =+'Abc '!F41 -> #REF! | E19: 605.14 | F19: 1283.37 | I19: =+SUM(D19:H19) -> #REF! | J19: 50.4 | K19: =+J19*I19 -> #REF!
A21: =+A19+1 -> 7 | B21: Tile Border (25mmx600) | C21: Rft | D21: =+'Abc '!F54 -> #REF! | E21: 57.34 | F21: 152.44 | I21: =+SUM(D21:H21) -> #REF! | J21: 33.6 | K21: =+J21*I21 -> #REF!
A23: =+A21+1 -> 8 | B23: Tile Groove Grouting | C23: Sft/Rft | D23: =+'Abc '!C80 -> #REF! | E23: 2005.82 | F23: 3087.56 | G23: 8972.03 | H23: 29.15 | I23: =+SUM(D23:H23) -> #REF! | J23: 26.4 | K23: =+J23*I23 -> #REF!
A25: =+A23+1 -> 9 | B25: Tile Acid wash Cleaning | C25: Sft/Rft | D25: =+'Abc '!C120 -> #REF! | E25: 4039.93 | F25: 6021.47 | G25: 9658.19 | H25: 1185.46 | I25: =+SUM(D25:H25) -> #REF! | J25: 4 | K25: =+J25*I25 -> #REF!
A27: =+A25+1 -> 10 | B27: Italian Marble Dado | C27: Sft | D27: =+'Abc '!C134 -> #REF! | E27: 578.7 | F27: 240.43 | G27: 793.82 | H27: 4.3 | I27: =+SUM(D27:H27) -> #REF! | J27: 110 | K27: =+J27*I27 -> #REF!
A29: =+A27+1 -> 11 | B29: Italian Marble Dado Mirror Polish | C29: Sft | D29: =+'Abc '!C148 -> #REF! | E29: 637.61 | F29: 240.43 | G29: 705.98 | H29: 4.3 | I29: =+SUM(D29:H29) -> #REF! | J29: 60 | K29: =+J29*I29 -> #REF!
A31: =+A29+1 -> 12 | B31: Italian Marble Border | C31: Rft | D31: =+'Abc '!F158 -> #REF! | E31: 1138.93 | F31: 1870.92 | G31: 1099.99 | H31: 110.14 | I31: =+SUM(D31:H31) -> #REF! | J31: 90 | K31: =+J31*I31 -> #REF!
A33: =+A31+1 -> 13 | B33: Italian Marble Border Mirror Polish | C33: Rft/Sft | D33: =+'Abc '!C213 -> #REF! | E33: 1223.65 | F33: 1790.06 | G33: 1072.57 | H33: 462.68 | I33: =+SUM(D33:H33) -> #REF! | J33: 60 | K33: =+J33*I33 -> #REF!
A35: =+A33+1 -> 14 | B35: Italian Marble Skirting | C35: Rft | D35: =+'Abc '!F188 -> #REF! | E35: 216.16 | F35: 497.77 | G35: 11.5 | I35: =+SUM(D35:H35) -> #REF! | J35: 90 | K35: =+J35*I35 -> #REF!
A37: =+A35+1 -> 15 | B37: Italian Marble Skirting Mirror Polish | C37: Rft | D37: =+'Abc '!F212 -> #REF! | E37: 246.3 | F37: 497.77 | G37: 11.5 | H37: 84.14 | I37: =+SUM(D37:H37) -> #REF! | J37: 60 | K37: =+J37*I37 -> #REF!
A39: =+A37+1 -> 16 | B39: Italian Marble Window/Door Jamb | C39: Rft | D39: =+'Abc '!C280 -> #REF! | E39: 891.75 | F39: 1536.6 | H39: 152.44 | I39: =+SUM(D39:H39) -> #REF! | J39: 90 | K39: =+J39*I39 -> #REF!
A41: =+A39+1 -> 17 | B41: Italian Marble Window/Door Jamb Mirror Polish | C41: Rft | D41: =+'Abc '!F278 -> #REF! | E41: 947.55 | F41: 1651.3 | H41: 152.44 | I41: =+SUM(D41:H41) -> #REF! | J41: 60 | K41: =+J41*I41 -> #REF!
A43: =+A41+1 -> 18 | B43: Italian Marble Counter | C43: Rft | D43: =+'Abc '!C292 -> #REF! | E43: 13.25 | F43: 24.75 | I43: =+SUM(D43:H43) -> #REF! | J43: 720 | K43: =+J43*I43 -> #REF!
A45: =+A43+1 -> 19 | B45: Italian Marble Basin Counter | C45: Rft | D45: =+'Abc '!C305 -> #REF! | E45: 34.98 | F45: 54.07 | I45: =+SUM(D45:H45) -> #REF! | J45: 720 | K45: =+J45*I45 -> #REF!
A47: =+A45+1 -> 20 | B47: Italian Marble Counter Top Mirror Polish | C47: Sft | D47: =+'Abc '!C318 -> #REF! | E47: 113.29 | F47: 153.31 | I47: =+SUM(D47:H47) -> #REF! | J47: 60 | K47: =+J47*I47 -> #REF!
A49: =+A47+1 -> 21 | B49: Italian Marble Floor | C49: Sft | D49: =+'Abc '!C320 -> #REF! | E49: 519.34 | F49: 438.48 | G49: 628.57 | H49: 174.09 | I49: =+SUM(D49:H49) -> #REF! | J49: 90 | K49: =+J49*I49 -> #REF!
A51: =+A49+1 -> 22 | B51: Italian Marble Desgin Floor | C51: Sft | D51: =+'Abc '!C322 -> #REF! | E51: 137.28 | F51: 137.28 | I51: =+SUM(D51:H51) -> #REF! | J51: 1100 | K51: =+J51*I51 -> #REF!
A53: =+A51+1 -> 23 | B53: Italian Marble Floor Mirror Polish | C53: Sft | D53: =+'Abc '!C327 -> #REF! | E53: 662.72 | F53: 575.76 | G53: 606.89 | H53: 174.09 | I53: =+SUM(D53:H53) -> #REF! | J53: 60 | K53: =+J53*I53 -> #REF!
A55: =+A53+1 -> 24 | B55: 9'' Design Skirting 4 Border Making & Polish | C55: Rft | D55: =+'Abc '!F281 -> #REF! | E55: 205.88 | F55: 180.9 | H55: 152.97 | I55: =+SUM(D55:H55) -> #REF! | J55: 1000 | K55: =+J55*I55 -> #REF!
A57: =+A55+1 -> 25 | B57: Granite Window Suport Jamb | C57: Rft | D57: =+'Abc '!F314 -> #REF! | E57: 471.17 | F57: 742.51 | G57: 1278.71 | H57: 202.24 | I57: =+SUM(D57:H57) -> #REF! | J57: 72 | K57: =+J57*I57 -> #REF!
A59: =+A57+1 -> 26 | B59: Granite Dado | C59: Sft | D59: =+'Abc '!F327 -> #REF! | F59: 100.79 | G59: 2.51 | I59: =+SUM(D59:H59) -> #REF! | J59: 72 | K59: =+J59*I59 -> #REF!
A61: =+A59+1 -> 27 | B61: Granite Floor | C61: Sft | D61: =+'Abc '!F329 -> #REF! | H61: 253.98 | I61: =+SUM(D61:H61) -> #REF! | J61: 72 | K61: =+J61*I61 -> #REF!
A63: =+A61+1 -> 28 | B63: Granite Skirting | C63: Rft | D63: =+'Abc '!F331 -> #REF! | G63: 37.62 | H63: 199.98 | I63: =+SUM(D63:H63) -> #REF! | J63: 66 | K63: =+J63*I63 -> #REF!
A65: =+A63+1 -> 29 | B65: Granite Border | C65: Rft | D65: =+'Abc '!C347 -> #REF! | F65: 159.5 | I65: =+SUM(D65:H65) -> #REF! | J65: 72 | K65: =+J65*I65 -> #REF!
A67: =+A65+1 -> 30 | B67: Granider Raugh Making | C67: Sft | D67: =+'Abc '!C360 -> #REF! | E67: 16.84 | F67: 247.79 | I67: =+SUM(D67:H67) -> #REF! | J67: 18 | K67: =+J67*I67 -> #REF!
A69: =+A67+1 -> 31 | B69: PCC Work | C69: Sft | D69: =+'Abc '!C374 -> #REF! | E69: 63.42 | F69: 121.38 | I69: =+SUM(D69:H69) -> #REF! | J69: 20.4 | K69: =+J69*I69 -> #REF!
A71: =+A69+1 -> 32 | B71: Demolish | C71: Sft | D71: =+'Abc '!C378 -> #REF! | E71: 122.3 | F71: 214 | I71: =+SUM(D71:H71) -> #REF! | J71: 21.6 | K71: =+J71*I71 -> #REF!
...
